2024-05-22 12:04:54,067 INFO     Running sw_w1_exp_sdc_conv.py
2024-05-22 12:04:55,232 ERROR    Gusto is logging this unhandled exception:
Traceback (most recent call last):
  File "/data/home/ab1679/sdc_williamson_conv/w1_conv/sw_w1_exp_sdc_conv.py", line 208, in <module>
    stepper.run(t=0, tmax=tmax)
  File "/data/home/ab1679/firedrake-june2024/src/gusto/gusto/timeloop.py", line 863, in run
    super().run(t, tmax, pick_up=pick_up)
  File "/data/home/ab1679/firedrake-june2024/src/gusto/gusto/timeloop.py", line 180, in run
    self.io.setup_dump(self.fields, t, pick_up)
  File "/data/home/ab1679/firedrake-june2024/src/gusto/gusto/io.py", line 405, in setup_dump
    raise GustoIOError(f'results directory {self.dumpdir} already exists')
gusto.io.GustoIOError: results directory results/will_1_ref3_dt900.0_k2_deg1 already exists
